Workbook

Sheet ItemizedPurchase
A1: Date | B1: Time | C1: Location | D1: Online | E1: InStore | F1: OrderTransID_ReceiptID | G1: ItemID | H1: Item | I1: Qty | J1: Qty_units | K1: PriceRaw
A2: 46022 | B2: 0.29166667 | C2: Amazon | D2: 1 | F2: 111-8892052-0363409 | H2: TAGMORE M12X1.5 Lug Nuts - 20pcs OEM Wheel Lug Nuts Compatible with 2009-18 Focus/2012-18 Fusion/2013-2020 Escape/2018+ EcoSport/2011-19 Fiesta, Chrome Acorn Wheel Nuts | K2: 19.99
A3: 46022 | B3: 0.29166667 | C3: Amazon | D3: 1 | F3: 111-8892052-0363409 | H3: Sales Tax | K3: 1.6
A4: 46022 | B4: 0.29166667 | C4: CollegeInvest | D4: 1 | H4: Isabella first semester success gift! $550 = ($90/A)(6 A) + ($5/Pass)(2 Pass) | K4: 550
A5: 46021 | B5: 0.83333333 | C5: Allegacy FCU | D5: 1 | H5: Hong Kong Station reimbursement | I5: 1 | J5: cnt | K5: -130
A6: 46021 | B6: 0.71041667 | C6: Hong Kong Station | D6: 1 | F6: #142 | G6: #17 | H6: Orange chicken | K6: 15.95
A7: 46021 | B7: 0.71041667 | C7: Hong Kong Station | D7: 1 | F7: #142 | G7: #01 | H7: Beef Chao Fan | K7: 16.95
A8: 46021 | B8: 0.71041667 | C8: Hong Kong Station | D8: 1 | F8: #142 | G8: #07 | H8: Salt and Pepper Tofu | K8: 15.95
A9: 46021 | B9: 0.71041667 | C9: Hong Kong Station | D9: 1 | F9: #142 | G9: #14 | H9: Salt and Pepper Shrimp (no head!) | K9: 17.95
A10: 46021 | B10: 0.71041667 | C10: Hong Kong Station | D10: 1 | F10: #142 | G10: #28 | H10: Garlic Yu Choy | K10: 15.95
A11: 46021 | B11: 0.71041667 | C11: Hong Kong Station | D11: 1 | F11: #142 | H11: Eggplant in Garlic Sauce (contains minced pork) | K11: 17.95
A12: 46021 | B12: 0.71041667 | C12: Hong Kong Station | D12: 1 | F12: #142 | G12: #06 | H12: Szechuan style spicy chicken (bone in) | K12: 17.95
A13: 46021 | B13: 0.71041667 | C13: Hong Kong Station | D13: 1 | F13: #142 | H13: 5 White Rice | K13: 0
A14: 46021 | B14: 0.71041667 | C14: Hong Kong Station | D14: 1 | F14: #142 | H14: Convenience Fee | K14: 1
A15: 46021 | B15: 0.71041667 | C15: Hong Kong Station | D15: 1 | F15: #142 | H15: Tax | K15: 8.01
A16: 46021 | C16: Pottery Barn | D16: 1 | F16: 353142751315 | H16: Mary Wu Christmas gift to Tovi (blanket cover) | I16: 1 | J16: cnt | K16: -81.46
A17: 46021 | C17: Amazon | D17: 1 | F17: GMCB-250121-1191665 | H17: **PENDING** Lydia Placeholder for GM 'retirement' gift >w< | I17: 4 | J17: cnt | K17: =280-105-83
A18: 46021 | C18: BELLA Health + Wellness | D18: 1 | H18: 10/27 Tovi Bilirubin visit ft. Drew Miller, PA | I18: 1 | J18: cnt | K18: 478
A19: 46021 | C19: Urgent Care Solutions GLE | D19: 1 | G19: 2025258BU0560 | H19: 9/7 Elisheva throw-up/diarrhea urgent care visit | I19: 1 | J19: cnt | K19: 117.06
A20: 46021 | C20: Labcorp OnDemand | G20: 2025115BI1381 | H20: 4/17 Lydia prenatal urine culture | I20: 1 | J20: cnt | K20: 14.71
A21: 46021 | H21: PLACEHOLDER: gate for sheva (100) | K21: 100
A22: 46021 | H22: Gift from Mary and Joseph Wu | I22: 1 | J22: cnt | K22: -79.99
A23: 46020 | B23: 0.40972222 | C23: StackSocial | D23: 1 | F23: 24804740 | G23: G4BB6-MPYWP-VKYPB-JMTDD-NV9JK | H23: Microsoft Windows 11 -- 2021 Office Suite | I23: 1 | J23: cnt | K23: 34.97
A24: 46020 | B24: 0.40972222 | C24: StackSocial | D24: 1 | F24: 24804740 | H24: Handling | K24: 1.99
A25: 46020 | B25: 0.40972222 | C25: StackSocial | D25: 1 | F25: 24804740 | H25: Tax | I25: 1 | J25: cnt | K25: 3.2
A26: 46020
A27: 46019
A28: 46018
A29: 46017 | B29: 0.41805556 | C29: Speedway | E29: 1 | H29: Subaru Gas ? Gallons @ $?/gal | K29: 16.94
A30: 46017 | B30: 0.41666667 | C30: Speedway | E30: 1 | H30: Subaru Gas ? Gallons @ $?/gal | K30: 15.28
A31: 46015 | B31: 0.35625 | C31: Two Chicks and a Hippie | E31: 1 | H31: Sticky Buns in Pagosa Springs | K31: 13.36
A32: 46015 | B32: 0.34861111 | C32: Two Chicks and a Hippie | E32: 1 | H32: Breakfast in Pagosa Springs | K32: 84.05
A33: 46015 | B33: 0.29166667 | C33: US Tax Witholding | D33: 1 | F33: RTX_Paycheck_25_52 | H33: Federal Income Tax | K33: 467.33
A34: 46015 | B34: 0.29166667 | C34: US Tax Witholding | D34: 1 | F34: RTX_Paycheck_25_52 | H34: Social Security Tax | K34: 353.38
A35: 46015 | B35: 0.29166667 | C35: US Tax Witholding | D35: 1 | F35: RTX_Paycheck_25_52 | H35: Medicare Tax | K35: 82.65
A36: 46015 | B36: 0.29166667 | C36: Raytheon | D36: 1 | F36: RTX_Paycheck_25_52 | G36: XXXX3523 | H36: Net Paycheck [Dec 6 - Dec 19] | K36: 3298.03
A37: 46015 | B37: 0.29166667 | C37: Raytheon | D37: 1 | F37: RTX_Paycheck_25_52 | H37: RTX Direct Deposit -- cancelling offset | K37: -3298.03
A38: 46015 | B38: 0.29166667 | C38: Raytheon | D38: 1 | F38: RTX_Paycheck_25_52 | H38: Gross Paycheck [Dec 6 - Dec 19] ($62.5000/hr) | K38: -5948.83
A39: 46015 | B39: 0.29166667 | C39: Raytheon | D39: 1 | F39: RTX_Paycheck_25_52 | H39: Ed(ucation) Assi(tance) Offset | K39: 948.83
A40: 46015 | B40: 0.29166667 | C40: Parents Gift Account | D40: 1 | F40: RTX_Paycheck_25_52 | G40: XXXX7146 | H40: Contribution to Parents Gift Account | K40: 0.01
...

Sheet ingredients
A1: Code | B1: Meal Name | C1: Ingredient | D1: Qt | E1: Unit | F1: Total | G1: CostTot | H1: CostQt
A2: A | B2: Mackerel Meatball | C2: Canned Mackerel | D2: 2 | E2: can | F2: 12 | G2: 17.71 | H2: =IFERROR(D2/F2*G2,0)
A3: A | B3: Mackerel Meatball | C3: Cucumber | D3: 0.66666667 | E3: cnt | F3: 3 | G3: 5.99 | H3: =IFERROR(D3/F3*G3,0)
A4: A | B4: Mackerel Meatball | C4: Dill | D4: 0.29 | E4: lb | F4: 1 | G4: 14.99 | H4: =IFERROR(D4/F4*G4,0)
A5: A | B5: Mackerel Meatball | C5: Egg | D5: 2 | E5: cnt | F5: 60 | G5: 9.39 | H5: =IFERROR(D5/F5*G5,0)
A6: A | B6: Mackerel Meatball | C6: Feta | D6: 0.5 | E6: cup | F6: 8 | G6: 6.99 | H6: =IFERROR(D6/F6*G6,0)
A7: A | B7: Mackerel Meatball | C7: Grapes | D7: 0.33333333 | E7: box | F7: 1 | G7: 5.89 | H7: =IFERROR(D7/F7*G7,0)
A8: A | B8: Mackerel Meatball | C8: Kale | D8: 1 | E8: bunch | F8: 3 | G8: 8.37 | H8: =IFERROR(D8/F8*G8,0)
A9: A | B9: Mackerel Meatball | C9: Lemon | D9: 1 | E9: cnt | F9: 1 | G9: 0.58 | H9: =IFERROR(D9/F9*G9,0)
A10: A | B10: Mackerel Meatball | C10: Lemon Juice | D10: 0.25 | E10: bottle | F10: 1 | G10: 1.69 | H10: =IFERROR(D10/F10*G10,0)
A11: A | B11: Mackerel Meatball | C11: Lime | D11: 1 | E11: cnt | F11: 1 | G11: 0.2 | H11: =IFERROR(D11/F11*G11,0)
A12: A | B12: Mackerel Meatball | C12: Olive Oil | D12: 4 | E12: tbsn | F12: 67.7 | G12: 27.99 | H12: =IFERROR(D12/F12*G12,0)
A13: A | B13: Mackerel Meatball | C13: Parsley | D13: 0.5 | E13: bunch | F13: 1 | G13: 0.99 | H13: =IFERROR(D13/F13*G13,0)
... A49: C | B49: Warm Chicken Grain Bowl | C49: Garlic Powder | D49: 2 | E49: tsp | F49: 60 | G49: 5.99 | H49: =IFERROR(D49/F49*G49,0)
A50: D | B50: Turkey Barley Soup | C50: Berries | D50: 9 | E50: oz | F50: 9 | G50: 2.98 | H50: =IFERROR(D41/F41*G41,0)
A51: D | B51: Turkey Barley Soup | C51: Carrots | D51: 1 | E51: lb | F51: 1 | G51: 0.98 | H51: =IFERROR(D42/F42*G42,0)
A52: D | B52: Turkey Barley Soup | C52: Carrots | D52: 1 | E52: lb | F52: 1 | G52: 0.98 | H52: =IFERROR(D43/F43*G43,0)
A53: D | B53: Turkey Barley Soup | C53: Celery | D53: 1 | E53: rib | F53: 4 | G53: 2.49 | H53: =IFERROR(D44/F44*G44,0)
A54: D | B54: Turkey Barley Soup | C54: ground turkey | D54: 1.72 | E54: lb | F54: 4 | G54: 24.99 | H54: =IFERROR(D45/F45*G45,0)
A55: D | B55: Turkey Barley Soup | C55: Parsley | D55: 0.5 | E55: bunch | F55: 1 | G55: 0.99 | H55: =IFERROR(D46/F46*G46,0)
A56: D | B56: Turkey Barley Soup | C56: pearl barley | D56: 1 | E56: bag | F56: 1 | G56: 1.58 | H56: =IFERROR(D47/F47*G47,0)
A57: D | B57: Turkey Barley Soup | C57: Purple Potato | D57: 2 | E57: lb | F57: 1 | G57: 2.49 | H57: =IFERROR(D48/F48*G48,0)
A58: D | B58: Turkey Barley Soup | C58: Salt and Pepper | D58: 0.25 | E58: tsp | F58: 26 | G58: 6.69 | H58: =IFERROR(D49/F49*G49,0)
A59: D | B59: Turkey Barley Soup | C59: Sourdough Bread | D59: 0.5 | E59: loaf | F59: 1 | G59: 4.5 | H59: =IFERROR(D50/F50*G50,0)
A60: D | B60: Turkey Barley Soup | C60: Tomato Sauce | D60: 1 | E60: can | F60: 12 | G60: 12.99 | H60: =IFERROR(D51/F51*G51,0)
A61: D | B61: Turkey Barley Soup | C61: Vegan Cheddar | D61: 2 | E61: slices | F61: 12 | G61: 6.99 | H61: =IFERROR(D52/F52*G52,0)
... A80: F | B80: Turkey Spaghetti | C80: Tomato Sauce | D80: 3 | E80: can | F80: 12 | G80: 12.99 | H80: =IFERROR(D71/F71*G71,0)
A81: Total | G81: =SUBTOTAL(109,Table31[CostTot]) | H81: =IFERROR(D72/F72*G72,0)
H82: =IFERROR(D73/F73*G73,0)
H83: =IFERROR(D74/F74*G74,0)
H84: =IFERROR(D75/F75*G75,0)
A85: Total | G85: =SUBTOTAL(109,Table31[CostTot]) | H85: =SUBTOTAL(109,Table31[CostQt])

Sheet totalMealCost
A1: Code | B1: Meal Name | C1: Total Meal Cost | D1: Servings | E1: Cost/Serving
A2: A | B2: Mackerel Meatball | C2: =SUMIF(ingredients!A:A,A2,ingredients!H:H) | D2: 5 | E2: =C2/D2
A3: B | B3: Kale & Chicken Pasta | C3: =SUMIF(ingredients!A:A,A3,ingredients!H:H) | D3: 6 | E3: =C3/D3
A4: C | B4: Warm Chicken Grain Bowl | C4: =SUMIF(ingredients!A:A,A4,ingredients!H:H) | D4: 8 | E4: =C4/D4
A5: D | B5: Chicken Barley Soup | C5: =SUMIF(ingredients!A:A,A5,ingredients!H:H) | D5: 8 | E5: =C5/D5
A6: E | B6: Mackerel Cauliflower Fried Rice | C6: =SUMIF(ingredients!A:A,A6,ingredients!H:H) | D6: 6 | E6: =C6/D6
A7: F | B7: Turkey Spaghetti | C7: =SUMIF(ingredients!A:A,A7,ingredients!H:H) | D7: 6 | E7: =C7/D7
